Internal Server Error: /user/6/
Traceback (most recent call last):
  File "/Users/tairsairanbekov/PycharmProjects/my_env/lib/python3.9/site-packages/django/core/handlers/exception.py", line 55, in inner
    response = get_response(request)
  File "/Users/tairsairanbekov/PycharmProjects/my_env/lib/python3.9/site-packages/django/core/handlers/base.py", line 197, in _get_response
    response = wrapped_callback(request, *callback_args, **callback_kwargs)
  File "/Users/tairsairanbekov/PycharmProjects/my_env/lib/python3.9/site-packages/django/views/decorators/csrf.py", line 54, in wrapped_view
    return view_func(*args, **kwargs)
  File "/Users/tairsairanbekov/PycharmProjects/my_env/lib/python3.9/site-packages/rest_framework/viewsets.py", line 125, in view
    return self.dispatch(request, *args, **kwargs)
  File "/Users/tairsairanbekov/PycharmProjects/my_env/lib/python3.9/site-packages/rest_framework/views.py", line 509, in dispatch
    response = self.handle_exception(exc)
  File "/Users/tairsairanbekov/PycharmProjects/my_env/lib/python3.9/site-packages/rest_framework/views.py", line 469, in handle_exception
    self.raise_uncaught_exception(exc)
  File "/Users/tairsairanbekov/PycharmProjects/my_env/lib/python3.9/site-packages/rest_framework/views.py", line 480, in raise_uncaught_exception
    raise exc
  File "/Users/tairsairanbekov/PycharmProjects/my_env/lib/python3.9/site-packages/rest_framework/views.py", line 506, in dispatch
    response = handler(request, *args, **kwargs)
  File "/Users/tairsairanbekov/PycharmProjects/BEHighLoad/api/views/vs.py", line 33, in partial_update
    logger.info(f'{data.username} updated')
AttributeError: 'dict' object has no attribute 'username'
"PATCH /user/6/ HTTP/1.1" 500 88958
Internal Server Error: /api/orders/
Traceback (most recent call last):
  File "/Users/tairsairanbekov/PycharmProjects/my_env/lib/python3.9/site-packages/django/core/handlers/exception.py", line 55, in inner
    response = get_response(request)
  File "/Users/tairsairanbekov/PycharmProjects/my_env/lib/python3.9/site-packages/django/core/handlers/base.py", line 197, in _get_response
    response = wrapped_callback(request, *callback_args, **callback_kwargs)
  File "/Users/tairsairanbekov/PycharmProjects/my_env/lib/python3.9/site-packages/django/views/decorators/csrf.py", line 54, in wrapped_view
    return view_func(*args, **kwargs)
  File "/Users/tairsairanbekov/PycharmProjects/my_env/lib/python3.9/site-packages/django/views/generic/base.py", line 84, in view
    return self.dispatch(request, *args, **kwargs)
  File "/Users/tairsairanbekov/PycharmProjects/my_env/lib/python3.9/site-packages/rest_framework/views.py", line 509, in dispatch
    response = self.handle_exception(exc)
  File "/Users/tairsairanbekov/PycharmProjects/my_env/lib/python3.9/site-packages/rest_framework/views.py", line 469, in handle_exception
    self.raise_uncaught_exception(exc)
  File "/Users/tairsairanbekov/PycharmProjects/my_env/lib/python3.9/site-packages/rest_framework/views.py", line 480, in raise_uncaught_exception
    raise exc
  File "/Users/tairsairanbekov/PycharmProjects/my_env/lib/python3.9/site-packages/rest_framework/views.py", line 506, in dispatch
    response = handler(request, *args, **kwargs)
  File "/Users/tairsairanbekov/PycharmProjects/BEHighLoad/api/views/cbv.py", line 139, in post
    if not buy_product(qty, prodId):
  File "/Users/tairsairanbekov/PycharmProjects/BEHighLoad/api/views/cbv.py", line 105, in buy_product
    for sing_id in prod_id:
TypeError: 'int' object is not iterable
"POST /api/orders/ HTTP/1.1" 500 92239
{'comment': [ErrorDetail(string='This field may not be blank.', code='blank')]}
Unavailable product quantity
{'comment': [ErrorDetail(string='This field may not be blank.', code='blank')]}
{'comment': [ErrorDetail(string='This field may not be blank.', code='blank')]}
